Workbook

Sheet ejercicio inyección
B1: Tasa base anual | C1: 0.06
B2: diario | C2: =+C1/360 -> 0.00016666667
B3: Capital inicial | C3: 1000000000
B5: Ejemplo inyección a 7 días
E6: En Bs.
B7: día | C7: Var % | D7: Valor en Bs. De la unidad de inversión | E7: Pago de rendimiento | F7: d/c interés | G7: d/c cambio actualización | H7: Principal | I7: Pago total
B8: 1 | D8: 100 | J8: 15000
B9: =1+B8 -> 2 | C9: 2 | D9: =+D8*(1+C9/100) -> 102 | E9: =+IF(D9<$D$8,$C$3*$C$2*B9,((D9/$D$8)*(1+$C$2*(B9-$B$8))-1)*$C$3) -> 20170000 | F9: =+IF(D9<$D$8,$C$3*$C$2*B9,($C$3/$D$8)*D9*$C$2*(B9-$B$8)) -> 170000 | G9: =+IF(D9<$D$8,0,$C$3*(D9/$D$8-1)) -> 20000000 | J9: =J8*(1+C9/100) -> 15300
B10: =1+B9 -> 3 | C10: 2 | D10: =+D9*(1+C10/100) -> 104.04 | E10: =+IF(D10<$D$8,$C$3*$C$2*B10,((D10/$D$8)*(1+$C$2*(B10-$B$8))-1)*$C$3) -> 40746800 | F10: =+IF(D10<$D$8,$C$3*$C$2*B10,($C$3/$D$8)*D10*$C$2*(B10-$B$8)) -> 346800 | G10: =+IF(D10<$D$8,0,$C$3*(D10/$D$8-1)) -> 40400000 | J10: =J9*(1+C10/100) -> 15606
B11: =1+B10 -> 4 | C11: 3 | D11: =+D10*(1+C11/100) -> 107.1612 | E11: =+IF(D11<$D$8,$C$3*$C$2*B11,((D11/$D$8)*(1+$C$2*(B11-$B$8))-1)*$C$3) -> 72147806 | F11: =+IF(D11<$D$8,$C$3*$C$2*B11,($C$3/$D$8)*D11*$C$2*(B11-$B$8)) -> 535806 | G11: =+IF(D11<$D$8,0,$C$3*(D11/$D$8-1)) -> 71612000 | J11: =J10*(1+C11/100) -> 16074.18
B12: =1+B11 -> 5 | C12: 0 | D12: =+D11*(1+C12/100) -> 107.1612 | E12: =+IF(D12<$D$8,$C$3*$C$2*B12,((D12/$D$8)*(1+$C$2*(B12-$B$8))-1)*$C$3) -> 72326408 | F12: =+IF(D12<$D$8,$C$3*$C$2*B12,($C$3/$D$8)*D12*$C$2*(B12-$B$8)) -> 714408 | G12: =+IF(D12<$D$8,0,$C$3*(D12/$D$8-1)) -> 71612000 | J12: =J11*(1+C12/100) -> 16074.18
A13: Sábado | B13: =1+B12 -> 6 | C13: -2 | D13: =+D12*(1+C13/100) -> 105.01798 | E13: =+IF(D13<$D$8,$C$3*$C$2*B13,((D13/$D$8)*(1+$C$2*(B13-$B$8))-1)*$C$3) -> 51054910 | F13: =+IF(D13<$D$8,$C$3*$C$2*B13,($C$3/$D$8)*D13*$C$2*(B13-$B$8)) -> 875149.8 | G13: =+IF(D13<$D$8,0,$C$3*(D13/$D$8-1)) -> 50179760 | J13: =J12*(1+C13/100) -> 15752.696
A14: Domingo | B14: =1+B13 -> 7 | C14: 2 | D14: =+D13*(1+C14/100) -> 107.11834 | E14: =+IF(D14<$D$8,$C$3*$C$2*B14,((D14/$D$8)*(1+$C$2*(B14-$B$8))-1)*$C$3) -> 72254539 | F14: =+IF(D14<$D$8,$C$3*$C$2*B14,($C$3/$D$8)*D14*$C$2*(B14-$B$8)) -> 1071183.4 | G14: =+IF(D14<$D$8,0,$C$3*(D14/$D$8-1)) -> 71183355 | J14: =J13*(1+C14/100) -> 16067.75
B15: =1+B14 -> 8 | C15: 2 | D15: =+D14*(1+C15/100) -> 109.2607 | E15: =+IF(D15<$D$8,$C$3*$C$2*B15,((D15/$D$8)*(1+$C$2*(B15-$B$8))-1)*$C$3) -> 93881730 | F15: =+IF(D15<$D$8,$C$3*$C$2*B15,($C$3/$D$8)*D15*$C$2*(B15-$B$8)) -> 1274708.2 | G15: =+IF(D15<$D$8,0,$C$3*(D15/$D$8-1)) -> 92607022 | H15: =+C3 -> 1000000000 | I15: =+H15+E15 -> 1.0938817e+09 | J15: =J14*(1+C15/100) -> 16389.105
G16: =+IF(D16<$D$8,0,$C$3*(D16/$D$8-1)) -> 0 | J16: =J15/J8 -> 1.092607 | K16: =J16*(1+6%/360*(7))-1 -> 0.09388173
E17: =LN(1+C9/100) -> 0.019802627
E18: =LN(1+C10/100) -> 0.019802627
E19: =LN(1+C11/100) -> 0.029558802
E20: =LN(1+C12/100) -> 0
E21: =LN(1+C13/100) -> -0.020202707
A22: troi | B22: tasa de rendimiento de las operaciones de inyección | E22: =LN(1+C14/100) -> 0.019802627
A23: tibai | B23: tasa de interés base anual para la inyección | E23: =LN(1+C15/100) -> 0.019802627
E24: =SUM(E17:E23) -> 0.088566604
E25: =EXP(E24) -> 1.092607

Sheet IDI 18MARZO
A1: dia | B1: fecha bcv | C1: dicom | D1: idi | E1: variacion
A2: lunes | B2: 43766 | C2: 20454.31 | D2: 100 | F2: 43766 | G2: =B2-F2 -> 0
A3: martes | B3: 43767 | C3: 21659.92 | D3: 105.89 | E3: =D3-D2 -> 5.89 | F3: 43767 | G3: =B3-F3 -> 0
A4: miércoles | B4: 43768 | C4: 23605.94 | D4: 115.41 | E4: =D4-D3 -> 9.52 | F4: 43768 | G4: =B4-F4 -> 0
A5: jueves | B5: 43769 | C5: 24415.07 | D5: 119.36 | E5: =D5-D4 -> 3.95 | F5: 43769 | G5: =B5-F5 -> 0
A6: viernes | B6: 43770 | C6: 23402.91 | D6: 114.42 | E6: =D6-D5 -> -4.94 | F6: 43770 | G6: =B6-F6 -> 0
A7: sábado | B7: 43771 | C7: 23402.91 | D7: 114.42 | E7: =D7-D6 -> 0 | F7: 43771 | G7: =B7-F7 -> 0
A8: domingo | B8: 43772 | C8: 23402.91 | D8: 114.42 | E8: =D8-D7 -> 0 | F8: 43772 | G8: =B8-F8 -> 0
A9: lunes | B9: 43773 | C9: 23402.91 | D9: 114.42 | E9: =D9-D8 -> 0 | F9: 43773 | G9: =B9-F9 -> 0
A10: martes | B10: 43774 | C10: 22493.91 | D10: 109.97 | E10: =D10-D9 -> -4.45 | F10: 43774 | G10: =B10-F10 -> 0
A11: miércoles | B11: 43775 | C11: 22715.94 | D11: 111.06 | E11: =D11-D10 -> 1.09 | F11: 43775 | G11: =B11-F11 -> 0
A12: jueves | B12: 43776 | C12: 23533.38 | D12: 115.05 | E12: =D12-D11 -> 3.99 | F12: 43776 | G12: =B12-F12 -> 0
A13: viernes | B13: 43777 | C13: 24228.33 | D13: 118.45 | E13: =D13-D12 -> 3.4 | F13: 43777 | G13: =B13-F13 -> 0
A14: sábado | B14: 43778 | C14: 24228.33 | D14: 118.45 | E14: =D14-D13 -> 0 | F14: 43778 | G14: =B14-F14 -> 0
... A139: viernes | B139: 43903 | C139: 73688.73 | D139: 360.26 | E139: =D139-D138 -> 0.19 | F139: 43903 | G139: =B139-F139 -> 0
A140: sábado | B140: 43904 | C140: 73688.73 | D140: 360.26 | E140: =D142-D139 -> 1.92 | F140: 43904 | G140: =B140-F140 -> 0
A141: domingo | B141: 43905 | C141: 73688.73 | D141: 360.26 | E141: =D143-D142 -> 0.32 | F141: 43905 | G141: =B141-F141 -> 0
A142: lunes | B142: 43906 | C142: 74081.87 | D142: 362.18 | E142: =D144-D143 -> -0.68 | F142: 43906 | G142: =B142-F142 -> 0
A143: martes | B143: 43907 | C143: 74146.48 | D143: 362.5 | E143: =D145-D144 -> -361.82 | F143: 43907 | G143: =B143-F143 -> 0
A144: miércoles | B144: 43908 | C144: 74007.97 | D144: 361.82 | E144: =D146-D145 -> 0 | F144: 43908 | G144: =B144-F144 -> 0

Sheet Tabla
A1: Capital | B1: Tasa | C1: Fechas | E1: Dias | F1: Intereses
A3: 1000000000 | B3: 0.06 | C3: 43832 | D3: 43833 | E3: =+D3-C3 -> 1 | F3: =+A3*B3/360*E3 -> 166666.67
A4: 1000000000 | B4: 0.06 | C4: =+D3 -> 43833 | D4: 43834 | E4: =+D4-C4 -> 1 | F4: =+A4*B4/360*E4 -> 166666.67
A5: 1000000000 | B5: 0.06 | C5: =+D4 -> 43834 | D5: 43835 | E5: =+D5-C5 -> 1 | F5: =+A5*B5/360*E5 -> 166666.67
A6: 1000000000 | B6: 0.06 | C6: =+D5 -> 43835 | D6: 43836 | E6: =+D6-C6 -> 1 | F6: =+A6*B6/360*E6 -> 166666.67
A7: 1000000000 | B7: 0.06 | C7: =+D6 -> 43836 | D7: 43837 | E7: =+D7-C7 -> 1 | F7: =+A7*B7/360*E7 -> 166666.67
A8: 1000000000 | B8: 0.06 | C8: =+D7 -> 43837 | D8: 43838 | E8: =+D8-C8 -> 1 | F8: =+A8*B8/360*E8 -> 166666.67
A9: 1000000000 | B9: 0.06 | C9: =+D8 -> 43838 | D9: 43839 | E9: =+D9-C9 -> 1 | F9: =+A9*B9/360*E9 -> 166666.67
A10: 1000000000 | B10: 0.06 | C10: =+D9 -> 43839 | D10: 43840 | E10: =+D10-C10 -> 1 | F10: =+A10*B10/360*E10 -> 166666.67
A11: 1000000000 | B11: 0.06 | C11: =+D10 -> 43840 | D11: 43841 | E11: =+D11-C11 -> 1 | F11: =+A11*B11/360*E11 -> 166666.67
A12: 1000000000 | B12: 0.06 | C12: =+D11 -> 43841 | D12: 43842 | E12: =+D12-C12 -> 1 | F12: =+A12*B12/360*E12 -> 166666.67
A13: 1000000000 | B13: 0.06 | C13: =+D12 -> 43842 | D13: 43843 | E13: =+D13-C13 -> 1 | F13: =+A13*B13/360*E13 -> 166666.67
A14: 1000000000 | B14: 0.06 | C14: =+D13 -> 43843 | D14: 43844 | E14: =+D14-C14 -> 1 | F14: =+A14*B14/360*E14 -> 166666.67
A15: 1000000000 | B15: 0.06 | C15: =+D14 -> 43844 | D15: 43845 | E15: =+D15-C15 -> 1 | F15: =+A15*B15/360*E15 -> 166666.67
... A32: 1000000000 | B32: 0.06 | C32: =+D31 -> 43861 | D32: 43862 | E32: =+D32-C32 -> 1 | F32: =+A32*B32/360*E32 -> 166666.67
E33: =SUM(E3:E32) -> 30 | F33: =SUM(F3:F32) -> 5000000

Sheet  30 dias (3)
A1: fecha de liquidacion | B1: 43878
A2: PALZO | B2: 30 DIAS
K3: 513.01.M.35 Rendimientos por los créditos comerciales vigentes objeto de las medidas establecidas por el BCV
A4: Tasa base anual | B4: 6
A5: mensual | B5: =+B4/12 -> 0.5 | C5: =+B4/360 -> 0.016666667 | K5: 513.01.M.36 Rendimientos por variación de créditos comerciales vigentes determinada según lo establecido por el BCV
A6: Capital inicial mm Bs. | B6: 1000000000
A7: Amortización | B7: AL VCTO | G7: =F14*D14 -> 0
A8: TIR (desde el punto de vista del prestamista, que pueda utlizar el flujo mensual nuevamente a la misma tasa) | B8: 629.39537
A9: Tasa afectiva anual paga por el deudor en un año
E10: Flujo en Unidades de valor (UVCC) | H10: Flujo en Bs.
A11: DIA | B11: Var % TC t | C11: Tasa i mensual (ibmc) | D11: Valor del "idi" en bolívares | E11: Pago de interés | F11: Amortización | G11: Pago total | H11: Pago de interés | I11: Amortización | L11: Pago total | M11: Saldo en final en MM UVCC | N11: Saldo final en MM Bs. | P11: 513.01.M.35 | Q11: 513.01.M.36
I12: Amortización cap inicial | J12: Componente de actualización | K12: Total | O12: 131-36 / 358 | P12: INTERESES DE YASIRA | Q12: DIFERENCIAL INTERESES
A13: 43878 | D13: =VLOOKUP(A13,'IDI 18MARZO'!B:D,3,0) -> 358.82 | M13: =+B6/D13 -> 2786912.7 | N13: 1000000000 | R13: =VLOOKUP(A13,'IDI 18MARZO'!B:D,3,0) -> 358.82
A14: 43879 | B14: 20 | C14: =+B4/360 -> 0.016666667 | D14: =IF(R14>$D$13,R14,$D$13) -> 359.2 | E14: =+M13*C14/100 -> 464.48544 | G14: =+E14+F14 -> 464.48544 | H14: =+E14*D14 -> 166843.17 | J14: =+F14*D14-I14 -> 0 | K14: =+F14*D14 -> 0 | L14: =+H14+K14 -> 166843.17 | M14: =+M13-F14 -> 2786912.7 | N14: =+M14*D14 -> 1.001059e+09 | O14: =+N14-N13 -> 1059026.8 | P14: 166666.67 | Q14: =H14-P14 -> 176.50447 | R14: =VLOOKUP(A14,'IDI 18MARZO'!B:D,3,0) -> 359.2 | S14: =R14-R13 -> 0.38
A15: 43880 | B15: 20 | C15: =+C14 -> 0.016666667 | D15: =IF(R15>$D$13,R15,$D$13) -> 360.67 | E15: =+M14*C15/100 -> 464.48544 | G15: =+E15+F15 -> 464.48544 | H15: =+E15*D15 -> 167525.96 | J15: =+F15*D15-I15 -> 0 | K15: =+F15*D15 -> 0 | L15: =+H15+K15 -> 167525.96 | M15: =+M14-F15 -> 2786912.7 | N15: =+M15*D15 -> 1.0051558e+09 | O15: =+N15-N14 -> 4096761.6 | P15: 166666.67 | Q15: =H15-P15 -> 859.29807 | R15: =VLOOKUP(A15,'IDI 18MARZO'!B:D,3,0) -> 360.67 | S15: =R15-R14 -> 1.47
A16: 43881 | B16: 20 | C16: =+C15 -> 0.016666667 | D16: =IF(R16>$D$13,R16,$D$13) -> 360.61 | E16: =+M15*C16/100 -> 464.48544 | G16: =+E16+F16 -> 464.48544 | H16: =+E16*D16 -> 167498.1 | J16: =+F16*D16-I16 -> 0 | K16: =+F16*D16 -> 0 | L16: =+H16+K16 -> 167498.1 | M16: =+M15-F16 -> 2786912.7 | N16: =+M16*D16 -> 1.0049886e+09 | O16: =+N16-N15 -> -167214.76 | P16: 166666.67 | Q16: =H16-P16 -> 831.42894 | R16: =VLOOKUP(A16,'IDI 18MARZO'!B:D,3,0) -> 360.61 | S16: =R16-R15 -> -0.06
A17: 43882 | B17: 20 | C17: =+C16 -> 0.016666667 | D17: =IF(R17>$D$13,R17,$D$13) -> 360.74 | E17: =+M16*C17/100 -> 464.48544 | G17: =+E17+F17 -> 464.48544 | H17: =+E17*D17 -> 167558.48 | J17: =+F17*D17-I17 -> 0 | K17: =+F17*D17 -> 0 | L17: =+H17+K17 -> 167558.48 | M17: =+M16-F17 -> 2786912.7 | N17: =+M17*D17 -> 1.0053509e+09 | O17: =+N17-N16 -> 362298.65 | P17: 166666.67 | Q17: =H17-P17 -> 891.81205 | R17: =VLOOKUP(A17,'IDI 18MARZO'!B:D,3,0) -> 360.74 | S17: =R17-R16 -> 0.13
A18: 43883 | B18: 15 | C18: =+C17 -> 0.016666667 | D18: =IF(R18>$D$13,R18,$D$13) -> 360.74 | E18: =+M17*C18/100 -> 464.48544 | G18: =+E18+F18 -> 464.48544 | H18: =+E18*D18 -> 167558.48 | J18: =+F18*D18-I18 -> 0 | K18: =+F18*D18 -> 0 | L18: =+H18+K18 -> 167558.48 | M18: =+M17-F18 -> 2786912.7 | N18: =+M18*D18 -> 1.0053509e+09 | O18: =+N18-N17 -> 0 | P18: 166666.67 | Q18: =H18-P18 -> 891.81205 | R18: =VLOOKUP(A18,'IDI 18MARZO'!B:D,3,0) -> 360.74 | S18: =R18-R17 -> 0
A19: 43884 | B19: 15 | C19: =+C18 -> 0.016666667 | D19: =IF(R19>$D$13,R19,$D$13) -> 360.74 | E19: =+M18*C19/100 -> 464.48544 | G19: =+E19+F19 -> 464.48544 | H19: =+E19*D19 -> 167558.48 | J19: =+F19*D19-I19 -> 0 | K19: =+F19*D19 -> 0 | L19: =+H19+K19 -> 167558.48 | M19: =+M18-F19 -> 2786912.7 | N19: =+M19*D19 -> 1.0053509e+09 | O19: =+N19-N18 -> 0 | P19: 166666.67 | Q19: =H19-P19 -> 891.81205 | R19: =VLOOKUP(A19,'IDI 18MARZO'!B:D,3,0) -> 360.74 | S19: =R19-R18 -> 0
A20: 43885 | B20: 15 | C20: =+C19 -> 0.016666667 | D20: =IF(R20>$D$13,R20,$D$13) -> 360.74 | E20: =+M19*C20/100 -> 464.48544 | G20: =+E20+F20 -> 464.48544 | H20: =+E20*D20 -> 167558.48 | J20: =+F20*D20-I20 -> 0 | K20: =+F20*D20 -> 0 | L20: =+H20+K20 -> 167558.48 | M20: =+M19-F20 -> 2786912.7 | N20: =+M20*D20 -> 1.0053509e+09 | O20: =+N20-N19 -> 0 | P20: 166666.67 | Q20: =H20-P20 -> 891.81205 | R20: =VLOOKUP(A20,'IDI 18MARZO'!B:D,3,0) -> 360.74 | S20: =R20-R19 -> 0
A21: 43886 | B21: 15 | C21: =+C20 -> 0.016666667 | D21: =IF(R21>$D$13,R21,$D$13) -> 360.74 | E21: =+M20*C21/100 -> 464.48544 | G21: =+E21+F21 -> 464.48544 | H21: =+E21*D21 -> 167558.48 | J21: =+F21*D21-I21 -> 0 | K21: =+F21*D21 -> 0 | L21: =+H21+K21 -> 167558.48 | M21: =+M20-F21 -> 2786912.7 | N21: =+M21*D21 -> 1.0053509e+09 | O21: =+N21-N20 -> 0 | P21: 166666.67 | Q21: =H21-P21 -> 891.81205 | R21: =VLOOKUP(A21,'IDI 18MARZO'!B:D,3,0) -> 360.74 | S21: =R21-R20 -> 0
A22: 43887 | B22: 10 | C22: =+C21 -> 0.016666667 | D22: =IF(R22>$D$13,R22,$D$13) -> 358.82 | E22: =+M21*C22/100 -> 464.48544 | G22: =+E22+F22 -> 464.48544 | H22: =+E22*D22 -> 166666.67 | J22: =+F22*D22-I22 -> 0 | K22: =+F22*D22 -> 0 | L22: =+H22+K22 -> 166666.67 | M22: =+M21-F22 -> 2786912.7 | N22: =+M22*D22 -> 1e+09 | O22: =+N22-N21 -> -5350872.3 | P22: 166666.67 | Q22: =H22-P22 -> 0 | R22: =VLOOKUP(A22,'IDI 18MARZO'!B:D,3,0) -> 358.61 | S22: =R22-R21 -> -2.13
A23: 43888 | B23: 10 | C23: =+C22 -> 0.016666667 | D23: =IF(R23>$D$13,R23,$D$13) -> 359.84 | E23: =+M22*C23/100 -> 464.48544 | G23: =+E23+F23 -> 464.48544 | H23: =+E23*D23 -> 167140.44 | J23: =+F23*D23-I23 -> 0 | K23: =+F23*D23 -> 0 | L23: =+H23+K23 -> 167140.44 | M23: =+M22-F23 -> 2786912.7 | N23: =+M23*D23 -> 1.0028427e+09 | O23: =+N23-N22 -> 2842650.9 | P23: 166666.67 | Q23: =H23-P23 -> 473.77515 | R23: =VLOOKUP(A23,'IDI 18MARZO'!B:D,3,0) -> 359.84 | S23: =R23-R22 -> 1.23
A24: 43889 | B24: 10 | C24: =+C23 -> 0.016666667 | D24: =IF(R24>$D$13,R24,$D$13) -> 360.08 | E24: =+M23*C24/100 -> 464.48544 | G24: =+E24+F24 -> 464.48544 | H24: =+E24*D24 -> 167251.92 | J24: =+F24*D24-I24 -> 0 | K24: =+F24*D24 -> 0 | L24: =+H24+K24 -> 167251.92 | M24: =+M23-F24 -> 2786912.7 | N24: =+M24*D24 -> 1.0035115e+09 | O24: =+N24-N23 -> 668859.04 | P24: 166666.67 | Q24: =H24-P24 -> 585.25166 | R24: =VLOOKUP(A24,'IDI 18MARZO'!B:D,3,0) -> 360.08 | S24: =R24-R23 -> 0.24
A25: 43890 | B25: 10 | C25: =+C24 -> 0.016666667 | D25: =IF(R25>$D$13,R25,$D$13) -> 360.08 | E25: =+M24*C25/100 -> 464.48544 | G25: =+E25+F25 -> 464.48544 | H25: =+E25*D25 -> 167251.92 | J25: =+F25*D25-I25 -> 0 | K25: =+F25*D25 -> 0 | L25: =+H25+K25 -> 167251.92 | M25: =+M24-F25 -> 2786912.7 | N25: =+M25*D25 -> 1.0035115e+09 | O25: =+N25-N24 -> 0 | P25: 166666.67 | Q25: =H25-P25 -> 585.25166 | R25: =VLOOKUP(A25,'IDI 18MARZO'!B:D,3,0) -> 360.08 | S25: =R25-R24 -> 0
A26: 43891 | B26: 10 | C26: =+C25 -> 0.016666667 | D26: =IF(R26>$D$13,R26,$D$13) -> 360.08 | E26: =+M25*C26/100 -> 464.48544 | G26: =+E26+F26 -> 464.48544 | H26: =+E26*D26 -> 167251.92 | J26: =+F26*D26-I26 -> 0 | K26: =+F26*D26 -> 0 | L26: =+H26+K26 -> 167251.92 | M26: =+M25-F26 -> 2786912.7 | N26: =+M26*D26 -> 1.0035115e+09 | O26: =+N26-N25 -> 0 | P26: 166666.67 | Q26: =H26-P26 -> 585.25166 | R26: =VLOOKUP(A26,'IDI 18MARZO'!B:D,3,0) -> 360.08 | S26: =R26-R25 -> 0
... A42: 43907 | B42: 10 | C42: =+C41 -> 0.016666667 | D42: =IF(R42>$D$13,R42,$D$13) -> 362.5 | E42: =+M41*C42/100 -> 464.48544 | G42: =+E42+F42 -> 464.48544 | H42: =+E42*D42 -> 168375.97 | J42: =+F42*D42-I42 -> 0 | K42: =+F42*D42 -> 0 | L42: =+H42+K42 -> 168375.97 | M42: =+M41-F42 -> 2786912.7 | N42: =+M42*D42 -> 1.0102558e+09 | O42: =+N42-N41 -> 891812.05 | P42: 166666.67 | Q42: =H42-P42 -> 1709.3064 | R42: =VLOOKUP(A42,'IDI 18MARZO'!B:D,3,0) -> 362.5 | S42: =R42-R41 -> 0.32
A43: 43908 | B43: 10 | C43: =+C42 -> 0.016666667 | D43: =IF(R43>$D$13,R43,$D$13) -> 361.82 | E43: =+M42*C43/100 -> 464.48544 | F43: =+M13 -> 2786912.7 | G43: =+E43+F43 -> 2787377.1 | H43: =+E43*D43 -> 168060.12 | I43: 1000000000 | J43: =+F43*D43-I43 -> 8360738 | K43: =+F43*D43 -> 1.0083607e+09 | L43: =+H43+K43 -> 1.0085288e+09 | M43: =+M42-F43 -> 0 | N43: =+M43*D43 -> 0 | O43: =SUM(O14:O42) -> 10255839 | P43: 166666.67 | Q43: =H43-P43 -> 1393.4563 | R43: =VLOOKUP(A43,'IDI 18MARZO'!B:D,3,0) -> 361.82 | S43: =R43-R42 -> -0.68
E44: =+SUM(E14:E43) -> 13934.563 | F44: =+SUM(F14:F43) -> 2786912.7 | G44: =+SUM(G14:G43) -> 2800847.2 | H44: =+SUM(H14:H43) -> 5020316.6 | I44: =+SUM(I14:I43) -> 1000000000 | J44: =+SUM(J14:J43) -> 8360738 | K44: =+SUM(K14:K43) -> 1.0083607e+09 | L44: =+SUM(L14:L43) -> 1.0133811e+09 | ... N44: =+SUM(N14:N43) -> 2.9113539e+10 | P44: =SUM(P14:P43) -> 5000000 | Q44: =H44-P44 -> 20316.593
O46: =O43-J43 -> 1895100.6

Sheet  30 dias (2)
A1: fecha de liquidacion | C1: 43878
A2: PALZO | C2: 30 DIAS
K3: 513.01.M.35 Rendimientos por los créditos comerciales vigentes objeto de las medidas establecidas por el BCV
A4: Tasa base anual | C4: 6
A5: mensual | C5: =+C4/12 -> 0.5 | D5: =+C4/360 -> 0.016666667 | K5: 513.01.M.36 Rendimientos por variación de créditos comerciales vigentes determinada según lo establecido por el BCV
A6: Capital inicial mm Bs. | C6: 35000000000
A7: Amortización | C7: AL VCTO | G7: =F14*D14 -> 0
A8: TIR (desde el punto de vista del prestamista, que pueda utlizar el flujo mensual nuevamente a la misma tasa) | C8: 629.39537
A9: Tasa afectiva anual paga por el deudor en un año
E10: Flujo en Unidades de valor (UVCC) | H10: Flujo en Bs.
A11: DIA | B11: Var % TC t | C11: Tasa i mensual (ibmc) | D11: Valor del "idi" en bolívares | E11: Pago de interés | F11: Amortización | G11: Pago total | H11: Pago de interés | I11: Amortización | L11: Pago total | M11: Saldo en final en MM UVCC | N11: Saldo final en MM Bs. | P11: 513.01.M.35 | Q11: 513.01.M.36
I12: Amortización cap inicial | J12: Componente de actualización | K12: Total | O12: 131-36 / 358 | P12: INTERESES DE YASIRA | Q12: DIFERENCIAL INTERESES
A13: =C1 -> 43878 | D13: =VLOOKUP(A13,'IDI 18MARZO'!B:D,3,0) -> 358.82 | M13: =+C6/D13 -> 97541943 | N13: =C6 -> 35000000000 | R13: =VLOOKUP(A13,'IDI 18MARZO'!B:D,3,0) -> 358.82
A14: 43879 | B14: 20 | C14: =+C4/360 -> 0.016666667 | D14: =IF(R14>$D$13,R14,$D$13) -> 359.2 | E14: =+M13*C14/100 -> 16256.991 | G14: =+E14+F14 -> 16256.991 | H14: =+E14*D14 -> 5839511 | J14: =+F14*D14-I14 -> 0 | K14: =+F14*D14 -> 0 | L14: =+H14+K14 -> 5839511 | M14: =+M13-F14 -> 97541943 | N14: =+M14*D14 -> 3.5037066e+10 | O14: =+N14-N13 -> 37065938 | P14: 166666.67 | Q14: =H14-P14 -> 5672844.3 | R14: =VLOOKUP(A14,'IDI 18MARZO'!B:D,3,0) -> 359.2 | S14: =R14-R13 -> 0.38
A15: 43880 | B15: 20 | C15: =+C14 -> 0.016666667 | D15: =IF(R15>$D$13,R15,$D$13) -> 360.67 | E15: =+M14*C15/100 -> 16256.991 | G15: =+E15+F15 -> 16256.991 | H15: =+E15*D15 -> 5863408.8 | J15: =+F15*D15-I15 -> 0 | K15: =+F15*D15 -> 0 | L15: =+H15+K15 -> 5863408.8 | M15: =+M14-F15 -> 97541943 | N15: =+M15*D15 -> 3.5180453e+10 | O15: =+N15-N14 -> 1.4338666e+08 | P15: 166666.67 | Q15: =H15-P15 -> 5696742.1 | R15: =VLOOKUP(A15,'IDI 18MARZO'!B:D,3,0) -> 360.67 | S15: =R15-R14 -> 1.47
A16: 43881 | B16: 20 | C16: =+C15 -> 0.016666667 | D16: =IF(R16>$D$13,R16,$D$13) -> 360.61 | E16: =+M15*C16/100 -> 16256.991 | G16: =+E16+F16 -> 16256.991 | H16: =+E16*D16 -> 5862433.3 | J16: =+F16*D16-I16 -> 0 | K16: =+F16*D16 -> 0 | L16: =+H16+K16 -> 5862433.3 | M16: =+M15-F16 -> 97541943 | N16: =+M16*D16 -> 3.51746e+10 | O16: =+N16-N15 -> -5852516.6 | P16: 166666.67 | Q16: =H16-P16 -> 5695766.7 | R16: =VLOOKUP(A16,'IDI 18MARZO'!B:D,3,0) -> 360.61 | S16: =R16-R15 -> -0.06
A17: 43882 | B17: 20 | C17: =+C16 -> 0.016666667 | D17: =IF(R17>$D$13,R17,$D$13) -> 360.74 | E17: =+M16*C17/100 -> 16256.991 | G17: =+E17+F17 -> 16256.991 | H17: =+E17*D17 -> 5864546.8 | J17: =+F17*D17-I17 -> 0 | K17: =+F17*D17 -> 0 | L17: =+H17+K17 -> 5864546.8 | M17: =+M16-F17 -> 97541943 | N17: =+M17*D17 -> 3.5187281e+10 | O17: =+N17-N16 -> 12680453 | P17: 166666.67 | Q17: =H17-P17 -> 5697880.1 | R17: =VLOOKUP(A17,'IDI 18MARZO'!B:D,3,0) -> 360.74 | S17: =R17-R16 -> 0.13
A18: 43883 | B18: 15 | C18: =+C17 -> 0.016666667 | D18: =IF(R18>$D$13,R18,$D$13) -> 360.74 | E18: =+M17*C18/100 -> 16256.991 | G18: =+E18+F18 -> 16256.991 | H18: =+E18*D18 -> 5864546.8 | J18: =+F18*D18-I18 -> 0 | K18: =+F18*D18 -> 0 | L18: =+H18+K18 -> 5864546.8 | M18: =+M17-F18 -> 97541943 | N18: =+M18*D18 -> 3.5187281e+10 | O18: =+N18-N17 -> 0 | P18: 166666.67 | Q18: =H18-P18 -> 5697880.1 | R18: =VLOOKUP(A18,'IDI 18MARZO'!B:D,3,0) -> 360.74 | S18: =R18-R17 -> 0
A19: 43884 | B19: 15 | C19: =+C18 -> 0.016666667 | D19: =IF(R19>$D$13,R19,$D$13) -> 360.74 | E19: =+M18*C19/100 -> 16256.991 | G19: =+E19+F19 -> 16256.991 | H19: =+E19*D19 -> 5864546.8 | J19: =+F19*D19-I19 -> 0 | K19: =+F19*D19 -> 0 | L19: =+H19+K19 -> 5864546.8 | M19: =+M18-F19 -> 97541943 | N19: =+M19*D19 -> 3.5187281e+10 | O19: =+N19-N18 -> 0 | P19: 166666.67 | Q19: =H19-P19 -> 5697880.1 | R19: =VLOOKUP(A19,'IDI 18MARZO'!B:D,3,0) -> 360.74 | S19: =R19-R18 -> 0
A20: 43885 | B20: 15 | C20: =+C19 -> 0.016666667 | D20: =IF(R20>$D$13,R20,$D$13) -> 360.74 | E20: =+M19*C20/100 -> 16256.991 | G20: =+E20+F20 -> 16256.991 | H20: =+E20*D20 -> 5864546.8 | J20: =+F20*D20-I20 -> 0 | K20: =+F20*D20 -> 0 | L20: =+H20+K20 -> 5864546.8 | M20: =+M19-F20 -> 97541943 | N20: =+M20*D20 -> 3.5187281e+10 | O20: =+N20-N19 -> 0 | P20: 166666.67 | Q20: =H20-P20 -> 5697880.1 | R20: =VLOOKUP(A20,'IDI 18MARZO'!B:D,3,0) -> 360.74 | S20: =R20-R19 -> 0
A21: 43886 | B21: 15 | C21: =+C20 -> 0.016666667 | D21: =IF(R21>$D$13,R21,$D$13) -> 360.74 | E21: =+M20*C21/100 -> 16256.991 | G21: =+E21+F21 -> 16256.991 | H21: =+E21*D21 -> 5864546.8 | J21: =+F21*D21-I21 -> 0 | K21: =+F21*D21 -> 0 | L21: =+H21+K21 -> 5864546.8 | M21: =+M20-F21 -> 97541943 | N21: =+M21*D21 -> 3.5187281e+10 | O21: =+N21-N20 -> 0 | P21: 166666.67 | Q21: =H21-P21 -> 5697880.1 | R21: =VLOOKUP(A21,'IDI 18MARZO'!B:D,3,0) -> 360.74 | S21: =R21-R20 -> 0
A22: 43887 | B22: 10 | C22: =+C21 -> 0.016666667 | D22: =IF(R22>$D$13,R22,$D$13) -> 358.82 | E22: =+M21*C22/100 -> 16256.991 | G22: =+E22+F22 -> 16256.991 | H22: =+E22*D22 -> 5833333.3 | J22: =+F22*D22-I22 -> 0 | K22: =+F22*D22 -> 0 | L22: =+H22+K22 -> 5833333.3 | M22: =+M21-F22 -> 97541943 | N22: =+M22*D22 -> 35000000000 | O22: =+N22-N21 -> -1.8728053e+08 | P22: 166666.67 | Q22: =H22-P22 -> 5666666.7 | R22: =VLOOKUP(A22,'IDI 18MARZO'!B:D,3,0) -> 358.61 | S22: =R22-R21 -> -2.13
A23: 43888 | B23: 10 | C23: =+C22 -> 0.016666667 | D23: =IF(R23>$D$13,R23,$D$13) -> 359.84 | E23: =+M22*C23/100 -> 16256.991 | G23: =+E23+F23 -> 16256.991 | H23: =+E23*D23 -> 5849915.5 | J23: =+F23*D23-I23 -> 0 | K23: =+F23*D23 -> 0 | L23: =+H23+K23 -> 5849915.5 | M23: =+M22-F23 -> 97541943 | N23: =+M23*D23 -> 3.5099493e+10 | O23: =+N23-N22 -> 99492782 | P23: 166666.67 | Q23: =H23-P23 -> 5683248.8 | R23: =VLOOKUP(A23,'IDI 18MARZO'!B:D,3,0) -> 359.84 | S23: =R23-R22 -> 1.23
A24: 43889 | B24: 10 | C24: =+C23 -> 0.016666667 | D24: =IF(R24>$D$13,R24,$D$13) -> 360.08 | E24: =+M23*C24/100 -> 16256.991 | G24: =+E24+F24 -> 16256.991 | H24: =+E24*D24 -> 5853817.1 | J24: =+F24*D24-I24 -> 0 | K24: =+F24*D24 -> 0 | L24: =+H24+K24 -> 5853817.1 | M24: =+M23-F24 -> 97541943 | N24: =+M24*D24 -> 3.5122903e+10 | O24: =+N24-N23 -> 23410066 | P24: 166666.67 | Q24: =H24-P24 -> 5687150.5 | R24: =VLOOKUP(A24,'IDI 18MARZO'!B:D,3,0) -> 360.08 | S24: =R24-R23 -> 0.24
A25: 43890 | B25: 10 | C25: =+C24 -> 0.016666667 | D25: =IF(R25>$D$13,R25,$D$13) -> 360.08 | E25: =+M24*C25/100 -> 16256.991 | G25: =+E25+F25 -> 16256.991 | H25: =+E25*D25 -> 5853817.1 | J25: =+F25*D25-I25 -> 0 | K25: =+F25*D25 -> 0 | L25: =+H25+K25 -> 5853817.1 | M25: =+M24-F25 -> 97541943 | N25: =+M25*D25 -> 3.5122903e+10 | O25: =+N25-N24 -> 0 | P25: 166666.67 | Q25: =H25-P25 -> 5687150.5 | R25: =VLOOKUP(A25,'IDI 18MARZO'!B:D,3,0) -> 360.08 | S25: =R25-R24 -> 0
A26: 43891 | B26: 10 | C26: =+C25 -> 0.016666667 | D26: =IF(R26>$D$13,R26,$D$13) -> 360.08 | E26: =+M25*C26/100 -> 16256.991 | G26: =+E26+F26 -> 16256.991 | H26: =+E26*D26 -> 5853817.1 | J26: =+F26*D26-I26 -> 0 | K26: =+F26*D26 -> 0 | L26: =+H26+K26 -> 5853817.1 | M26: =+M25-F26 -> 97541943 | N26: =+M26*D26 -> 3.5122903e+10 | O26: =+N26-N25 -> 0 | P26: 166666.67 | Q26: =H26-P26 -> 5687150.5 | R26: =VLOOKUP(A26,'IDI 18MARZO'!B:D,3,0) -> 360.08 | S26: =R26-R25 -> 0
... A42: 43907 | B42: 10 | C42: =+C41 -> 0.016666667 | D42: =IF(R42>$D$13,R42,$D$13) -> 362.5 | E42: =+M41*C42/100 -> 16256.991 | G42: =+E42+F42 -> 16256.991 | H42: =+E42*D42 -> 5893159.1 | J42: =+F42*D42-I42 -> 0 | K42: =+F42*D42 -> 0 | L42: =+H42+K42 -> 5893159.1 | M42: =+M41-F42 -> 97541943 | N42: =+M42*D42 -> 3.5358954e+10 | O42: =+N42-N41 -> 31213422 | P42: 166666.67 | Q42: =H42-P42 -> 5726492.4 | R42: =VLOOKUP(A42,'IDI 18MARZO'!B:D,3,0) -> 362.5 | S42: =R42-R41 -> 0.32
A43: 43908 | B43: 10 | C43: =+C42 -> 0.016666667 | D43: =IF(R43>$D$13,R43,$D$13) -> 361.82 | E43: =+M42*C43/100 -> 16256.991 | F43: =+M13 -> 97541943 | G43: =+E43+F43 -> 97558200 | H43: =+E43*D43 -> 5882104.3 | I43: =C6 -> 35000000000 | J43: =+F43*D43-I43 -> 2.9262583e+08 | K43: =+F43*D43 -> 3.5292626e+10 | L43: =+H43+K43 -> 3.5298508e+10 | M43: =+M42-F43 -> 0 | N43: =+M43*D43 -> 0 | O43: =SUM(O14:O42) -> 3.5895435e+08 | P43: 166666.67 | Q43: =H43-P43 -> 5715437.6 | R43: =VLOOKUP(A43,'IDI 18MARZO'!B:D,3,0) -> 361.82 | S43: =R43-R42 -> -0.68
E44: =+SUM(E14:E43) -> 487709.72 | F44: =+SUM(F14:F43) -> 97541943 | G44: =+SUM(G14:G43) -> 98029653 | H44: =+SUM(H14:H43) -> 1.7571108e+08 | I44: =+SUM(I14:I43) -> 35000000000 | J44: =+SUM(J14:J43) -> 2.9262583e+08 | K44: =+SUM(K14:K43) -> 3.5292626e+10 | L44: =+SUM(L14:L43) -> 3.5468337e+10 | ... N44: =+SUM(N14:N43) -> 1.0189739e+12 | P44: =SUM(P14:P43) -> 5000000 | Q44: =H44-P44 -> 1.7071108e+08
O46: =O43-J43 -> 66328521
M47: =N42-K43 -> 66328521

Sheet 30 dias 
A1: fecha de liquidacion | C1: 43816
A2: plazo | C2: 90 dias
K3: 513.01.M.35 Rendimientos por los créditos comerciales vigentes objeto de las medidas establecidas por el BCV
A4: Tasa de interes anual | C4: 6
A5: mensual | C5: =+C4/12 -> 0.5 | D5: =+C4/360 -> 0.016666667 | K5: 513.01.M.36 Rendimientos por variación de créditos comerciales vigentes determinada según lo establecido por el BCV
A6: Amortización | C6: AL VCTO | G6: =F45*D45 -> 0
A7: TIR (desde el punto de vista del prestamista, que pueda utlizar el flujo mensual nuevamente a la misma tasa) | C7: 629.39537
A8: Tasa afectiva anual paga por el deudor en un año
C10: TASA MENSUAL | D10: Bs | F10: Ganancia o Perdida mensual bco | H10: TASA ANUAL
A11: Capital inicial mm Bs. | D11: 35000000000
A12: cobro MENSUAL bs | C12: 0.2 | D12: =D11*C12 -> 7000000000 | H12: =C12*12 -> 2.4
A13: Costo del encaje o financiamiento bs | C13: 0.105 | D13: =-D11*C13 -> -3675000000 | F13: =D12+D13 -> 3325000000 | H13: =C13*12 -> 1.26
A16: el cobro mensual incluye
A17: intereses | C17: 0.005 | F17: =C17 -> 0.005 | H17: =C17*12 -> 0.06
A18: flat desembolso | C18: 0.005 | F18: 0 | H18: =C18*12 -> 0.06
A19: asesoria | C19: =C12-C17-C18 -> 0.19 | D19: y depues del rmer mes | F19: =C19+C18 -> 0.195 | H19: =C19*12 -> 2.28
A22: importante: el credito con UVCC , ajusta diariamente el monto del capital de acuerdo al desplazamiento del IDI
A23: El cliente debe considerar el impacto del desplazamento del tipo de cambio en el costo o pago a la banca.
A24: este ejercicio corresponde a un credito otorgado el 15 de febrero a 30 dias, de acuerdo al comportamiento del IDI
A25: PLAZO | C25: 30 | D25: total | E25: tasa mensual | F25: tasa trimestral | G25: tasa anual
A26: total intereses bs | C26: mensual | D26: =H75 -> 1.6921515e+08
A27: total amortizacion | C27: vcto | D27: =I74 -> 35000000000
A28: total capital indexado | C28: =C2 -> 90 dias | D28: =J75 -> 50592094
A29: total comision asesoria | C29: mensual | D29: =D12 -> 7000000000
A30: total a pagar a vcto | D30: =SUM(D26:D29) -> 4.2219807e+10 | E30: =D39/D27 -> 0.20628021
E33: =D27*E30 -> 7.2198072e+09
E34: =E33*3 -> 2.1659422e+10 | F34: =D27*F30 -> 0
E35: =E34*4 -> 8.6637687e+10 | G35: =D27*G30 -> 0
C39: costo | D39: =D30-D27 -> 7.2198072e+09 | E39: =D27*E30 -> 7.2198072e+09 | F39: =D27*F30 -> 0
E41: Flujo en Unidades de valor (UVCC) | H41: Flujo en Bs.
A42: DIA | B42: Var % TC t | C42: Tasa i mensual (ibmc) | D42: Valor del "idi" en bolívares | E42: Pago de interés | F42: Amortización | G42: Pago total | H42: Pago de interés | I42: Amortización | L42: Pago total | M42: Saldo en final en MM UVCC | N42: Saldo final en MM Bs. | P42: 513.01.M.35 | Q42: 513.01.M.36
I43: Amortización cap inicial | J43: Componente de actualización | K43: Total | O43: 131-36 / 358 | P43: INTERESES DE YASIRA | Q43: DIFERENCIAL INTERESES
A44: 43876 | D44: 359.74 | M44: =+D11/D44 -> 97292489 | N44: =D11 -> 35000000000 | R44: =VLOOKUP(A44,'IDI 18MARZO'!B:D,3,0) -> 359.74
A45: 43877 | B45: 20 | C45: =+C4/360 -> 0.016666667 | D45: 359.74 | E45: =+M44*C45/100 -> 16215.415 | G45: =+E45+F45 -> 16215.415 | H45: =+E45*D45 -> 5833333.3 | J45: =+F45*D45-I45 -> 0 | K45: =+F45*D45 -> 0 | L45: =+H45+K45 -> 5833333.3 | M45: =+M44-F45 -> 97292489 | N45: =+M45*D45 -> 35000000000 | O45: =+N45-N44 -> 0 | P45: 166666.67 | Q45: =H45-P45 -> 5666666.7 | R45: =VLOOKUP(A45,'IDI 18MARZO'!B:D,3,0) -> 359.74 | S45: =R45-R44 -> 0
A46: 43878 | B46: 20 | C46: =+C45 -> 0.016666667 | D46: 358.82 | E46: =+M45*C46/100 -> 16215.415 | G46: =+E46+F46 -> 16215.415 | H46: =+E46*D46 -> 5818415.2 | J46: =+F46*D46-I46 -> 0 | K46: =+F46*D46 -> 0 | L46: =+H46+K46 -> 5818415.2 | M46: =+M45-F46 -> 97292489 | N46: =+M46*D46 -> 3.4910491e+10 | O46: =+N46-N45 -> -89509090 | P46: 166666.67 | Q46: =H46-P46 -> 5651748.5 | R46: =VLOOKUP(A46,'IDI 18MARZO'!B:D,3,0) -> 358.82 | S46: =R46-R45 -> -0.92
A47: 43879 | B47: 20 | C47: =+C46 -> 0.016666667 | D47: 359.2 | E47: =+M46*C47/100 -> 16215.415 | G47: =+E47+F47 -> 16215.415 | H47: =+E47*D47 -> 5824577 | J47: =+F47*D47-I47 -> 0 | K47: =+F47*D47 -> 0 | L47: =+H47+K47 -> 5824577 | M47: =+M46-F47 -> 97292489 | N47: =+M47*D47 -> 3.4947462e+10 | O47: =+N47-N46 -> 36971146 | P47: 166666.67 | Q47: =H47-P47 -> 5657910.3 | R47: =VLOOKUP(A47,'IDI 18MARZO'!B:D,3,0) -> 359.2 | S47: =R47-R46 -> 0.38
A48: 43880 | B48: 20 | C48: =+C47 -> 0.016666667 | D48: 360.67 | E48: =+M47*C48/100 -> 16215.415 | G48: =+E48+F48 -> 16215.415 | H48: =+E48*D48 -> 5848413.7 | J48: =+F48*D48-I48 -> 0 | K48: =+F48*D48 -> 0 | L48: =+H48+K48 -> 5848413.7 | M48: =+M47-F48 -> 97292489 | N48: =+M48*D48 -> 3.5090482e+10 | O48: =+N48-N47 -> 1.4301996e+08 | P48: 166666.67 | Q48: =H48-P48 -> 5681747 | R48: =VLOOKUP(A48,'IDI 18MARZO'!B:D,3,0) -> 360.67 | S48: =R48-R47 -> 1.47
A49: 43881 | B49: 15 | C49: =+C48 -> 0.016666667 | D49: 360.61 | E49: =+M48*C49/100 -> 16215.415 | G49: =+E49+F49 -> 16215.415 | H49: =+E49*D49 -> 5847440.7 | J49: =+F49*D49-I49 -> 0 | K49: =+F49*D49 -> 0 | L49: =+H49+K49 -> 5847440.7 | M49: =+M48-F49 -> 97292489 | N49: =+M49*D49 -> 3.5084644e+10 | O49: =+N49-N48 -> -5837549.3 | P49: 166666.67 | Q49: =H49-P49 -> 5680774.1 | R49: =VLOOKUP(A49,'IDI 18MARZO'!B:D,3,0) -> 360.61 | S49: =R49-R48 -> -0.06
A50: 43882 | B50: 15 | C50: =+C49 -> 0.016666667 | D50: 360.74 | E50: =+M49*C50/100 -> 16215.415 | G50: =+E50+F50 -> 16215.415 | H50: =+E50*D50 -> 5849548.7 | J50: =+F50*D50-I50 -> 0 | K50: =+F50*D50 -> 0 | L50: =+H50+K50 -> 5849548.7 | M50: =+M49-F50 -> 97292489 | N50: =+M50*D50 -> 3.5097292e+10 | O50: =+N50-N49 -> 12648024 | P50: 166666.67 | Q50: =H50-P50 -> 5682882.1 | R50: =VLOOKUP(A50,'IDI 18MARZO'!B:D,3,0) -> 360.74 | S50: =R50-R49 -> 0.13
A51: 43883 | B51: 15 | C51: =+C50 -> 0.016666667 | D51: 360.74 | E51: =+M50*C51/100 -> 16215.415 | G51: =+E51+F51 -> 16215.415 | H51: =+E51*D51 -> 5849548.7 | J51: =+F51*D51-I51 -> 0 | K51: =+F51*D51 -> 0 | L51: =+H51+K51 -> 5849548.7 | M51: =+M50-F51 -> 97292489 | N51: =+M51*D51 -> 3.5097292e+10 | O51: =+N51-N50 -> 0 | P51: 166666.67 | Q51: =H51-P51 -> 5682882.1 | R51: =VLOOKUP(A51,'IDI 18MARZO'!B:D,3,0) -> 360.74 | S51: =R51-R50 -> 0
...

Sheet  90 dias (3)
A1: fecha de liquidacion | C1: 43816
A2: plazo | C2: 90 dias
K3: 513.01.M.35 Rendimientos por los créditos comerciales vigentes objeto de las medidas establecidas por el BCV
A4: Tasa de interes anual | C4: 6
A5: mensual | C5: =+C4/12 -> 0.5 | D5: =+C4/360 -> 0.016666667 | K5: 513.01.M.36 Rendimientos por variación de créditos comerciales vigentes determinada según lo establecido por el BCV
A6: Amortización | C6: AL VCTO | G6: =F45*D45 -> 0
A7: TIR (desde el punto de vista del prestamista, que pueda utlizar el flujo mensual nuevamente a la misma tasa) | C7: 629.39537
A8: Tasa afectiva anual paga por el deudor en un año
C10: TASA MENSUAL | D10: Bs | F10: Ganancia o Perdida mensual bco | H10: TASA ANUAL
A11: Capital inicial mm Bs. | D11: 35000000000
A12: cobro MENSUAL bs | C12: 0.105 | D12: =D11*C12 -> 3675000000 | H12: =C12*12 -> 1.26
A13: Costo del encaje o financiamiento bs | C13: 0.105 | D13: =-D11*C13 -> -3675000000 | F13: =D12+D13 -> 0 | H13: =C13*12 -> 1.26
A16: el cobro mensual incluye
A17: intereses | C17: 0.005 | F17: =C17 -> 0.005 | H17: =C17*12 -> 0.06
A18: flat desembolso | C18: 0.005 | F18: 0 | H18: =C18*12 -> 0.06
A19: asesoria | C19: =C12-C17-C18 -> 0.095 | D19: y depues del rmer mes | F19: =C19+C18 -> 0.1 | H19: =C19*12 -> 1.14
A22: importante: el credito con UVCC , ajusta diariamente el monto del capital de acuerdo al desplazamiento del IDI
A23: El cliente debe considerar el impacto del desplazamento del tipo de cambio en el costo o pago a la banca.
A24: este ejercicio corresponde a un credito otorgado el 17 de diciembre a 90 dias, de acuerdo al comportamiento del IDI
A25: PLAZO | C25: 89 | D25: total | E25: tasa mensual | F25: tasa trimestral | G25: tasa anual
A26: total intereses bs | C26: mensual | D26: =H135 -> 7.4538229e+08
A27: total amortizacion | C27: vcto | D27: =I134 -> 35000000000
A28: total capital indexado | C28: 89 DIAS | D28: =J134 -> 2.062511e+10
A29: total comision asesoria | C29: mensual | D29: =+D11*10%*3 -> 10500000000
A30: total a pagar a vcto | D30: =SUM(D26:D29) -> 6.6870493e+10 | E30: =(F30/C25)*30 -> 0.30693893 | F30: =D39/D27 -> 0.9105855 | G30: =E30*12 -> 3.6832672
E33: =D27*E30 -> 1.0742863e+10
E34: =E33*3 -> 3.2228588e+10 | F34: =D27*F30 -> 3.1870493e+10
E35: =E34*4 -> 1.2891435e+11 | G35: =D27*G30 -> 1.2891435e+11
D39: =D30-D27 -> 3.1870493e+10 | E39: =D27*E30 -> 1.0742863e+10 | F39: =D27*F30 -> 3.1870493e+10
E41: Flujo en Unidades de valor (UVCC) | H41: Flujo en Bs.
A42: DIA | B42: Var % TC t | C42: Tasa i mensual (ibmc) | D42: Valor del "idi" en bolívares | E42: Pago de interés | F42: Amortización | G42: Pago total | H42: Pago de interés | I42: Amortización | L42: Pago total | M42: Saldo en final en MM UVCC | N42: Saldo final en MM Bs. | P42: 513.01.M.35 | Q42: 513.01.M.36
I43: Amortización cap inicial | J43: Componente de actualización | K43: Total | O43: 131-36 / 358 | P43: INTERESES DE YASIRA | Q43: DIFERENCIAL INTERESES
A44: =C1 -> 43816 | D44: =VLOOKUP(A44,'IDI 18MARZO'!B:D,3,0) -> 226.68 | M44: =+D11/D44 -> 1.5440268e+08 | N44: =D11 -> 35000000000 | R44: =VLOOKUP(A44,'IDI 18MARZO'!B:D,3,0) -> 226.68
A45: 43817 | B45: 20 | C45: =+C4/360 -> 0.016666667 | D45: =IF(R45>$D$44,R45,$D$44) -> 229.52 | E45: =+M44*C45/100 -> 25733.78 | G45: =+E45+F45 -> 25733.78 | H45: =+E45*D45 -> 5906417.3 | J45: =+F45*D45-I45 -> 0 | K45: =+F45*D45 -> 0 | L45: =+H45+K45 -> 5906417.3 | M45: =+M44-F45 -> 1.5440268e+08 | N45: =+M45*D45 -> 3.5438504e+10 | O45: =+N45-N44 -> 4.3850362e+08 | P45: 166666.67 | Q45: =H45-P45 -> 5739750.6 | R45: =VLOOKUP(A45,'IDI 18MARZO'!B:D,3,0) -> 229.52 | S45: =R45-R44 -> 2.84
A46: 43818 | B46: 20 | C46: =+C45 -> 0.016666667 | D46: =IF(R46>$D$44,R46,$D$44) -> 234.39 | E46: =+M45*C46/100 -> 25733.78 | G46: =+E46+F46 -> 25733.78 | H46: =+E46*D46 -> 6031740.8 | J46: =+F46*D46-I46 -> 0 | K46: =+F46*D46 -> 0 | L46: =+H46+K46 -> 6031740.8 | M46: =+M45-F46 -> 1.5440268e+08 | N46: =+M46*D46 -> 3.6190445e+10 | O46: =+N46-N45 -> 7.5194106e+08 | P46: 166666.67 | Q46: =H46-P46 -> 5865074.1 | R46: =VLOOKUP(A46,'IDI 18MARZO'!B:D,3,0) -> 234.39 | S46: =R46-R45 -> 4.87
A47: 43819 | B47: 20 | C47: =+C46 -> 0.016666667 | D47: =IF(R47>$D$44,R47,$D$44) -> 230.6 | E47: =+M46*C47/100 -> 25733.78 | G47: =+E47+F47 -> 25733.78 | H47: =+E47*D47 -> 5934209.8 | J47: =+F47*D47-I47 -> 0 | K47: =+F47*D47 -> 0 | L47: =+H47+K47 -> 5934209.8 | M47: =+M46-F47 -> 1.5440268e+08 | N47: =+M47*D47 -> 3.5605259e+10 | O47: =+N47-N46 -> -5.8518617e+08 | P47: 166666.67 | Q47: =H47-P47 -> 5767543.1 | R47: =VLOOKUP(A47,'IDI 18MARZO'!B:D,3,0) -> 230.6 | S47: =R47-R46 -> -3.79
A48: 43820 | B48: 20 | C48: =+C47 -> 0.016666667 | D48: =IF(R48>$D$44,R48,$D$44) -> 230.6 | E48: =+M47*C48/100 -> 25733.78 | G48: =+E48+F48 -> 25733.78 | H48: =+E48*D48 -> 5934209.8 | J48: =+F48*D48-I48 -> 0 | K48: =+F48*D48 -> 0 | L48: =+H48+K48 -> 5934209.8 | M48: =+M47-F48 -> 1.5440268e+08 | N48: =+M48*D48 -> 3.5605259e+10 | O48: =+N48-N47 -> 0 | P48: 166666.67 | Q48: =H48-P48 -> 5767543.1 | R48: =VLOOKUP(A48,'IDI 18MARZO'!B:D,3,0) -> 230.6 | S48: =R48-R47 -> 0
A49: 43821 | B49: 15 | C49: =+C48 -> 0.016666667 | D49: =IF(R49>$D$44,R49,$D$44) -> 230.6 | E49: =+M48*C49/100 -> 25733.78 | G49: =+E49+F49 -> 25733.78 | H49: =+E49*D49 -> 5934209.8 | J49: =+F49*D49-I49 -> 0 | K49: =+F49*D49 -> 0 | L49: =+H49+K49 -> 5934209.8 | M49: =+M48-F49 -> 1.5440268e+08 | N49: =+M49*D49 -> 3.5605259e+10 | O49: =+N49-N48 -> 0 | P49: 166666.67 | Q49: =H49-P49 -> 5767543.1 | R49: =VLOOKUP(A49,'IDI 18MARZO'!B:D,3,0) -> 230.6 | S49: =R49-R48 -> 0
A50: 43822 | B50: 15 | C50: =+C49 -> 0.016666667 | D50: =IF(R50>$D$44,R50,$D$44) -> 228.2 | E50: =+M49*C50/100 -> 25733.78 | G50: =+E50+F50 -> 25733.78 | H50: =+E50*D50 -> 5872448.7 | J50: =+F50*D50-I50 -> 0 | K50: =+F50*D50 -> 0 | L50: =+H50+K50 -> 5872448.7 | M50: =+M49-F50 -> 1.5440268e+08 | N50: =+M50*D50 -> 3.5234692e+10 | O50: =+N50-N49 -> -3.7056644e+08 | P50: 166666.67 | Q50: =H50-P50 -> 5705782 | R50: =VLOOKUP(A50,'IDI 18MARZO'!B:D,3,0) -> 228.2 | S50: =R50-R49 -> -2.4
A51: 43823 | B51: 15 | C51: =+C50 -> 0.016666667 | D51: =IF(R51>$D$44,R51,$D$44) -> 228.2 | E51: =+M50*C51/100 -> 25733.78 | G51: =+E51+F51 -> 25733.78 | H51: =+E51*D51 -> 5872448.7 | J51: =+F51*D51-I51 -> 0 | K51: =+F51*D51 -> 0 | L51: =+H51+K51 -> 5872448.7 | M51: =+M50-F51 -> 1.5440268e+08 | N51: =+M51*D51 -> 3.5234692e+10 | O51: =+N51-N50 -> 0 | P51: 166666.67 | Q51: =H51-P51 -> 5705782 | R51: =VLOOKUP(A51,'IDI 18MARZO'!B:D,3,0) -> 228.2 | S51: =R51-R50 -> 0
...

Sheet 120 dias 
A1: fecha de liquidación | C1: 43786
A2: PALZO | C2: 30 DIAS
K3: 513.01.M.35 Rendimientos por los créditos comerciales vigentes objeto de las medidas establecidas por el BCV
A4: Tasa base anual | C4: 6
A5: mensual | C5: =+C4/12 -> 0.5 | D5: =+C4/360 -> 0.016666667 | K5: 513.01.M.36 Rendimientos por variación de créditos comerciales vigentes determinada según lo establecido por el BCV
A6: Capital inicial mm Bs. | C6: 1000000000
A7: Amortización | C7: AL VCTO | G7: =F14*D14 -> 0
A8: TIR (desde el punto de vista del prestamista, que pueda utlizar el flujo mensual nuevamente a la misma tasa) | C8: 629.39537
E10: Flujo en Unidades de valor (UVCC) | H10: Flujo en Bs.
A11: DIA | B11: Var % TC t | C11: Tasa i mensual (ibmc) | D11: Valor del "idi" en bolívares | E11: Pago de interés | F11: Amortización | G11: Pago total | H11: Pago de interés | I11: Amortización | L11: Pago total | M11: Saldo en final en MM UVCC | N11: Saldo final en MM Bs. | P11: 513.01.M.35 | Q11: 513.01.M.36
I12: Amortización cap inicial | J12: Componente de actualización | K12: Total | O12: 131-36 / 358 | P12: INTERESES DE YASIRA | Q12: DIFERENCIAL INTERESES
A13: =C1 -> 43786 | D13: =VLOOKUP(A13,'IDI 18MARZO'!B:D,3,0) -> 147.09 | M13: =+C6/D13 -> 6798558.7 | N13: =C6 -> 1000000000 | R13: =VLOOKUP(A13,'IDI 18MARZO'!B:D,3,0) -> 147.09
A14: 43787 | B14: 20 | C14: =+C4/360 -> 0.016666667 | D14: =IF(R14>$D$13,R14,$D$13) -> 147.09 | E14: =+M13*C14/100 -> 1133.0931 | G14: =+E14+F14 -> 1133.0931 | H14: =+E14*D14 -> 166666.67 | J14: =+F14*D14-I14 -> 0 | K14: =+F14*D14 -> 0 | L14: =+H14+K14 -> 166666.67 | M14: =+M13-F14 -> 6798558.7 | N14: =+M14*D14 -> 1000000000 | O14: =+N14-N13 -> 0 | P14: 166666.67 | Q14: =H14-P14 -> 0 | R14: =VLOOKUP(A14,'IDI 18MARZO'!B:D,3,0) -> 143.65 | S14: =R14-R13 -> -3.44
A15: 43788 | B15: 20 | C15: =+C14 -> 0.016666667 | D15: =IF(R15>$D$13,R15,$D$13) -> 147.09 | E15: =+M14*C15/100 -> 1133.0931 | G15: =+E15+F15 -> 1133.0931 | H15: =+E15*D15 -> 166666.67 | J15: =+F15*D15-I15 -> 0 | K15: =+F15*D15 -> 0 | L15: =+H15+K15 -> 166666.67 | M15: =+M14-F15 -> 6798558.7 | N15: =+M15*D15 -> 1000000000 | O15: =+N15-N14 -> 0 | P15: 166666.67 | Q15: =H15-P15 -> 0 | R15: =VLOOKUP(A15,'IDI 18MARZO'!B:D,3,0) -> 141.56 | S15: =R15-R14 -> -2.09
A16: 43789 | B16: 20 | C16: =+C15 -> 0.016666667 | D16: =IF(R16>$D$13,R16,$D$13) -> 148.8 | E16: =+M15*C16/100 -> 1133.0931 | G16: =+E16+F16 -> 1133.0931 | H16: =+E16*D16 -> 168604.26 | J16: =+F16*D16-I16 -> 0 | K16: =+F16*D16 -> 0 | L16: =+H16+K16 -> 168604.26 | M16: =+M15-F16 -> 6798558.7 | N16: =+M16*D16 -> 1.0116255e+09 | O16: =+N16-N15 -> 11625535 | P16: 166666.67 | Q16: =H16-P16 -> 1937.5892 | R16: =VLOOKUP(A16,'IDI 18MARZO'!B:D,3,0) -> 148.8 | S16: =R16-R15 -> 7.24
A17: 43790 | B17: 20 | C17: =+C16 -> 0.016666667 | D17: =IF(R17>$D$13,R17,$D$13) -> 156.92 | E17: =+M16*C17/100 -> 1133.0931 | G17: =+E17+F17 -> 1133.0931 | H17: =+E17*D17 -> 177804.97 | J17: =+F17*D17-I17 -> 0 | K17: =+F17*D17 -> 0 | L17: =+H17+K17 -> 177804.97 | M17: =+M16-F17 -> 6798558.7 | N17: =+M17*D17 -> 1.0668298e+09 | O17: =+N17-N16 -> 55204297 | P17: 166666.67 | Q17: =H17-P17 -> 11138.305 | R17: =VLOOKUP(A17,'IDI 18MARZO'!B:D,3,0) -> 156.92 | S17: =R17-R16 -> 8.12
A18: 43791 | B18: 15 | C18: =+C17 -> 0.016666667 | D18: =IF(R18>$D$13,R18,$D$13) -> 157.38 | E18: =+M17*C18/100 -> 1133.0931 | G18: =+E18+F18 -> 1133.0931 | H18: =+E18*D18 -> 178326.19 | J18: =+F18*D18-I18 -> 0 | K18: =+F18*D18 -> 0 | L18: =+H18+K18 -> 178326.19 | M18: =+M17-F18 -> 6798558.7 | N18: =+M18*D18 -> 1.0699572e+09 | O18: =+N18-N17 -> 3127337 | P18: 166666.67 | Q18: =H18-P18 -> 11659.528 | R18: =VLOOKUP(A18,'IDI 18MARZO'!B:D,3,0) -> 157.38 | S18: =R18-R17 -> 0.46
A19: 43792 | B19: 15 | C19: =+C18 -> 0.016666667 | D19: =IF(R19>$D$13,R19,$D$13) -> 157.38 | E19: =+M18*C19/100 -> 1133.0931 | G19: =+E19+F19 -> 1133.0931 | H19: =+E19*D19 -> 178326.19 | J19: =+F19*D19-I19 -> 0 | K19: =+F19*D19 -> 0 | L19: =+H19+K19 -> 178326.19 | M19: =+M18-F19 -> 6798558.7 | N19: =+M19*D19 -> 1.0699572e+09 | O19: =+N19-N18 -> 0 | P19: 166666.67 | Q19: =H19-P19 -> 11659.528 | R19: =VLOOKUP(A19,'IDI 18MARZO'!B:D,3,0) -> 157.38 | S19: =R19-R18 -> 0
A20: 43793 | B20: 15 | C20: =+C19 -> 0.016666667 | D20: =IF(R20>$D$13,R20,$D$13) -> 157.38 | E20: =+M19*C20/100 -> 1133.0931 | G20: =+E20+F20 -> 1133.0931 | H20: =+E20*D20 -> 178326.19 | J20: =+F20*D20-I20 -> 0 | K20: =+F20*D20 -> 0 | L20: =+H20+K20 -> 178326.19 | M20: =+M19-F20 -> 6798558.7 | N20: =+M20*D20 -> 1.0699572e+09 | O20: =+N20-N19 -> 0 | P20: 166666.67 | Q20: =H20-P20 -> 11659.528 | R20: =VLOOKUP(A20,'IDI 18MARZO'!B:D,3,0) -> 157.38 | S20: =R20-R19 -> 0
A21: 43794 | B21: 15 | C21: =+C20 -> 0.016666667 | D21: =IF(R21>$D$13,R21,$D$13) -> 159.57 | E21: =+M20*C21/100 -> 1133.0931 | G21: =+E21+F21 -> 1133.0931 | H21: =+E21*D21 -> 180807.67 | J21: =+F21*D21-I21 -> 0 | K21: =+F21*D21 -> 0 | L21: =+H21+K21 -> 180807.67 | M21: =+M20-F21 -> 6798558.7 | N21: =+M21*D21 -> 1.084846e+09 | O21: =+N21-N20 -> 14888844 | P21: 166666.67 | Q21: =H21-P21 -> 14141.002 | R21: =VLOOKUP(A21,'IDI 18MARZO'!B:D,3,0) -> 159.57 | S21: =R21-R20 -> 2.19
A22: 43795 | B22: 10 | C22: =+C21 -> 0.016666667 | D22: =IF(R22>$D$13,R22,$D$13) -> 163.15 | E22: =+M21*C22/100 -> 1133.0931 | G22: =+E22+F22 -> 1133.0931 | H22: =+E22*D22 -> 184864.14 | J22: =+F22*D22-I22 -> 0 | K22: =+F22*D22 -> 0 | L22: =+H22+K22 -> 184864.14 | M22: =+M21-F22 -> 6798558.7 | N22: =+M22*D22 -> 1.1091849e+09 | O22: =+N22-N21 -> 24338840 | P22: 166666.67 | Q22: =H22-P22 -> 18197.475 | R22: =VLOOKUP(A22,'IDI 18MARZO'!B:D,3,0) -> 163.15 | S22: =R22-R21 -> 3.58
A23: 43796 | B23: 10 | C23: =+C22 -> 0.016666667 | D23: =IF(R23>$D$13,R23,$D$13) -> 173.41 | E23: =+M22*C23/100 -> 1133.0931 | G23: =+E23+F23 -> 1133.0931 | H23: =+E23*D23 -> 196489.68 | J23: =+F23*D23-I23 -> 0 | K23: =+F23*D23 -> 0 | L23: =+H23+K23 -> 196489.68 | M23: =+M22-F23 -> 6798558.7 | N23: =+M23*D23 -> 1.1789381e+09 | O23: =+N23-N22 -> 69753212 | P23: 166666.67 | Q23: =H23-P23 -> 29823.011 | R23: =VLOOKUP(A23,'IDI 18MARZO'!B:D,3,0) -> 173.41 | S23: =R23-R22 -> 10.26
A24: 43797 | B24: 10 | C24: =+C23 -> 0.016666667 | D24: =IF(R24>$D$13,R24,$D$13) -> 179.59 | E24: =+M23*C24/100 -> 1133.0931 | G24: =+E24+F24 -> 1133.0931 | H24: =+E24*D24 -> 203492.19 | J24: =+F24*D24-I24 -> 0 | K24: =+F24*D24 -> 0 | L24: =+H24+K24 -> 203492.19 | M24: =+M23-F24 -> 6798558.7 | N24: =+M24*D24 -> 1.2209532e+09 | O24: =+N24-N23 -> 42015093 | P24: 166666.67 | Q24: =H24-P24 -> 36825.526 | R24: =VLOOKUP(A24,'IDI 18MARZO'!B:D,3,0) -> 179.59 | S24: =R24-R23 -> 6.18
A25: 43798 | B25: 10 | C25: =+C24 -> 0.016666667 | D25: =IF(R25>$D$13,R25,$D$13) -> 186.78 | E25: =+M24*C25/100 -> 1133.0931 | G25: =+E25+F25 -> 1133.0931 | H25: =+E25*D25 -> 211639.13 | J25: =+F25*D25-I25 -> 0 | K25: =+F25*D25 -> 0 | L25: =+H25+K25 -> 211639.13 | M25: =+M24-F25 -> 6798558.7 | N25: =+M25*D25 -> 1.2698348e+09 | O25: =+N25-N24 -> 48881637 | P25: 166666.67 | Q25: =H25-P25 -> 44972.466 | R25: =VLOOKUP(A25,'IDI 18MARZO'!B:D,3,0) -> 186.78 | S25: =R25-R24 -> 7.19
A26: 43799 | B26: 10 | C26: =+C25 -> 0.016666667 | D26: =IF(R26>$D$13,R26,$D$13) -> 186.78 | E26: =+M25*C26/100 -> 1133.0931 | G26: =+E26+F26 -> 1133.0931 | H26: =+E26*D26 -> 211639.13 | J26: =+F26*D26-I26 -> 0 | K26: =+F26*D26 -> 0 | L26: =+H26+K26 -> 211639.13 | M26: =+M25-F26 -> 6798558.7 | N26: =+M26*D26 -> 1.2698348e+09 | O26: =+N26-N25 -> 0 | P26: 166666.67 | Q26: =H26-P26 -> 44972.466 | R26: =VLOOKUP(A26,'IDI 18MARZO'!B:D,3,0) -> 186.78 | S26: =R26-R25 -> 0
... A131: 43904 | B131: 10 | C131: =+C130 -> 0.016666667 | D131: =IF(R131>$D$13,R131,$D$13) -> 360.26 | E131: =+M130*C131/100 -> 1133.0931 | G131: =+E131+F131 -> 1133.0931 | H131: =+E131*D131 -> 408208.13 | J131: =+F131*D131-I131 -> 0 | K131: =+F131*D131 -> 0 | L131: =+H131+K131 -> 408208.13 | M131: =+M130-F131 -> 6798558.7 | N131: =+M131*D131 -> 2.4492488e+09 | O131: =+N131-N130 -> 0 | P131: 166666.67 | Q131: =H131-P131 -> 241541.46 | R131: =VLOOKUP(A131,'IDI 18MARZO'!B:D,3,0) -> 360.26 | S131: =R131-R130 -> 0
A132: 43905 | B132: 10 | C132: =+C131 -> 0.016666667 | D132: =IF(R132>$D$13,R132,$D$13) -> 360.26 | E132: =+M131*C132/100 -> 1133.0931 | F132: =+M102 -> 6798558.7 | G132: =+E132+F132 -> 6799691.8 | H132: =+E132*D132 -> 408208.13 | I132: =C6 -> 1000000000 | J132: =+F132*D132-I132 -> 1.4492488e+09 | K132: =+F132*D132 -> 2.4492488e+09 | L132: =+H132+K132 -> 2.449657e+09 | M132: =+M131-F132 -> 0 | N132: =+M132*D132 -> 0 | O132: =SUM(O14:O131) -> 1.4492488e+09 | P132: 166666.67 | Q132: =H132-P132 -> 241541.46 | R132: =VLOOKUP(A132,'IDI 18MARZO'!B:D,3,0) -> 360.26 | S132: =R132-R131 -> 0
